Workbook

Sheet Stats
C2: 10s | G2: 80s | K2: 140s
B3: Cells/ml | C3: Average yield | D3: SD yield | E3: Aveage viability | F3: SD viability | G3: Average yield | H3: SD yield | I3: Aveage viability | J3: SD viability | K3: Average yield | L3: SD yield | M3: Aveage viability | N3: SD viability
B4: 50000 | C4: =AVERAGE('50 000 cells ul'!B49:C49) -> 0.91358182 | D4: =STDEV('50 000 cells ul'!B50:C52) -> 0.071449524 | E4: =AVERAGE('50 000 cells ul'!B47:C47) -> 0.86333333 | F4: =STDEV('50 000 cells ul'!B41,'50 000 cells ul'!C41,'50 000 cells ul'!C43,'50 000 cells ul'!B43,'50 000 cells ul'!B45,'50 000 cells ul'!C45) -> 0.064935866 | G4: =AVERAGE('50 000 cells ul'!D49,'50 000 cells ul'!E49) -> 0.80247273 | H4: =STDEV('50 000 cells ul'!D50:E52) -> 0.18416634 | I4: =AVERAGE('50 000 cells ul'!D47:E47) -> 0.91666667 | J4: =STDEV('50 000 cells ul'!E45,'50 000 cells ul'!F45,'50 000 cells ul'!F43,'50 000 cells ul'!E43,'50 000 cells ul'!E41,'50 000 cells ul'!F41) -> 0.057503623 | K4: =AVERAGE('50 000 cells ul'!F49:G49) -> 0.62490303 | L4: =STDEV('50 000 cells ul'!F50:G52) -> 0.15275445 | M4: =AVERAGE('50 000 cells ul'!F47:G47) -> 0.93833333 | N4: =STDEV('50 000 cells ul'!F41,'50 000 cells ul'!G41,'50 000 cells ul'!G43,'50 000 cells ul'!F43,'50 000 cells ul'!F45,'50 000 cells ul'!G45) -> 0.049966656
B5: 20000 | C5: =AVERAGE('30000 cellsml'!B49:C49) -> 1.2932813 | D5: =STDEV('30000 cellsml'!B50:C52) -> 0.48004145 | E5: =AVERAGE('30000 cellsml'!B47:C47) -> 0.89333333 | F5: =STDEV('30000 cellsml'!B41,'30000 cellsml'!C41,'30000 cellsml'!C43,'30000 cellsml'!B43,'30000 cellsml'!B45,'30000 cellsml'!C45) -> 0.017511901 | G5: =AVERAGE('30000 cellsml'!D49:E49) -> 0.60642992 | H5: =STDEV('30000 cellsml'!D50:E52) -> 0.078995848 | I5: =AVERAGE('30000 cellsml'!D47:E47) -> 0.95 | J5: =STDEV('30000 cellsml'!D45,'30000 cellsml'!E45,'30000 cellsml'!E43,'30000 cellsml'!D43,'30000 cellsml'!D41,'30000 cellsml'!E41) -> 0.048579831 | K5: =AVERAGE('30000 cellsml'!F49:G49) -> 0.546875 | L5: =STDEV('30000 cellsml'!F50:G52) -> 0.093227712 | M5: =AVERAGE('30000 cellsml'!F47:G47) -> 0.95333333 | N5: =STDEV('30000 cellsml'!F41,'30000 cellsml'!G41,'30000 cellsml'!G43,'30000 cellsml'!F43,'30000 cellsml'!F45,'30000 cellsml'!G45) -> 0.032659863

Sheet 50000
A1: Time | B1: Viability | C1: SD_v | D1: Retention | E1: SD_r
A2: 30 | B2: 0.86 | C2: 0.064935866 | D2: 0.91358182 | E2: 0.071449524
A3: 120 | B3: 0.91666667 | C3: 0.057503623 | D3: 0.80247273 | E3: 0.18416634
A4: 240 | B4: 0.93833333 | C4: 0.049966656 | D4: 0.62490303 | E4: 0.15275445

Sheet Retention
A1: Concentration | B1: T1 | C1: T2 | D1: T3
A2: 50000 | B2: 0.93174545 | C2: 0.93992727 | D2: 0.64780606
A3: 50000 | B3: 0.89541818 | C3: 0.66501818 | D3: 0.602
A4: 30000 | B4: 0.86864583 | C4: 0.55208333 | D4: 0.515625
A5: 30000 | B5: 0.84927083 | C5: 0.66077652 | D5: 0.578125

Sheet Viabiltiy
A1: Concentration | B1: T1 | C1: T2 | D1: T3
A2: 50000 | B2: 0.88666667 | C2: 0.95 | D2: 0.92333333
A3: 50000 | B3: 0.84 | C3: 0.88333333 | D3: 0.95333333
A4: 30000 | B4: 0.88 | C4: 0.93333333 | D4: 0.94666667
A5: 30000 | B5: 0.90666667 | C5: 0.96666667 | D5: 0.96

Sheet 20000
A1: Time | B1: Viability | C1: SD_v | D1: Retention | E1: SD_r
A2: 30 | B2: 0.89333333 | C2: 0.017511901 | D2: 0.85895833 | E2: 0.067789431
A3: 120 | B3: 0.95 | C3: 0.048579831 | D3: 0.60642992 | E3: 0.078995848
A4: 240 | B4: 0.95333333 | C4: 0.032659863 | D4: 0.546875 | E4: 0.093227712

Sheet 50 000 cells ul
A1: Thawing
A2: Media prepared:
A3: Tube Nr:
A4: Taken from freezer:
A5: Arrival at water bath
A6: Taken out from the water bath | B6: 0.6150463
A7: Volume resuspended in (mL): | B7: 20
A8: Time at initial count: | B8: 0.62083333
A9: End thaw | B9: 0.62135417
A10: Volume resuspended in after spin down (mL): | B10: 10 | C10: Time: | D10: 0.62552083
A11: Divided to 6 tubes | B11: 0.62716435 | C11: Volume each tube: | D11: =2750000*B10/C18 -> 1.6961349 | E11: Actual volume: | F11: 1.7
A13: Cell counts after thaw
B14: Tot | C14: Live | D14: Viable
A15: Count 1 | B15: 800000 | C15: =B15*D15 -> 760000 | D15: 0.95
A16: Count 2 | B16: 832000 | C16: =B16*D16 -> 832000 | D16: 1
A17: Count 3 | B17: 840000 | C17: =B17*D17 -> 840000 | D17: 1
B18: Tot viabal: | C18: =AVERAGE(C15:C17)*B7 -> 16213333
A21: Falcone tube: | B21: 10s | D21: 80s | F21: 140s
B22: 1 | C22: 2 | D22: 3 | E22: 4 | F22: 5 | G22: 6
A23: Start time (Out from centrifuge)
A24: Cells given to injector
A25: Start Time inject
A26: End time injection
A27: Start time flush:
A28: End time flush
A29: Tube handed to Jesper
A30: Volume handed (uL) | B30: 90 | C30: 60 | D30: 60 | E30: 60 | F30: 55 | G30: 50
A31: Cells handed to injector | B31: 2750000 | C31: 2750000 | D31: 2750000 | E31: 2750000 | F31: 2750000 | G31: 2750000
A32: After Syringe (uL) | B32: 90 | C32: 60 | D32: 60 | E32: 60 | F32: 55 | G32: 50
A33: Cells injected | B33: =B31*B32/B30 -> 2750000 | C33: =C31*C32/C30 -> 2750000 | D33: =D31*D32/D30 -> 2750000 | E33: =E31*E32/E30 -> 2750000 | F33: =F31*F32/F30 -> 2750000 | G33: =G31*G32/G30 -> 2750000
A35: Volume flushed (uL) | B35: 100 | C35: 100 | D35: 100 | E35: 100 | F35: 100 | G35: 100
A36: Volume before (ml) | B36: 2 | C36: 2 | D36: 2 | E36: 2 | F36: 2 | G36: 2
A37: Volume after | B37: =B36+B32/1000+B35/1000 -> 2.19 | C37: =C36+C32/1000+C35/1000 -> 2.16 | D37: =D36+D32/1000+D35/1000 -> 2.16 | E37: =E36+E32/1000+E35/1000 -> 2.16 | F37: =F36+F32/1000+F35/1000 -> 2.155 | G37: =G36+G32/1000+G35/1000 -> 2.15
A38: JESPER COUNTS | B38: 0.65190972 | C38: 0.65763889 | D38: 0.66255787 | E38: 0.66969907 | F38: 0.67530093 | G38: 0.68206019
A39: Comments: | B39: White material end of cath
A40: Count 1 cells/ml | B40: 1210000 | C40: 1100000 | D40: 1400000 | E40: 960000 | F40: 880000 | G40: 760000
A41: Count 1 viability | B41: 0.82 | C41: 0.9 | D41: 0.95 | E41: 0.85 | F41: 0.87 | G41: 0.96
A42: Count 2 cells/ml | B42: 1200000 | C42: 1220000 | D42: 1090000 | E42: 720000 | F42: 1100000 | G42: 760000
A43: Count 2 viability | B43: 0.85 | C43: 0.85 | D43: 0.95 | E43: 0.86 | F43: 0.9 | G43: 0.98
A44: Count 3 cells/ml | B44: 1100000 | C44: 1000000 | D44: 1100000 | E44: 860000 | F44: 500000 | G44: 790000
...

Sheet 30000 cellsml
A1: Thawing
A2: Media prepared:
A3: Tube Nr:
A4: Taken from freezer:
A5: Arrival at water bath
A6: Taken out from the water bath | B6: 0.6150463
A7: Volume resuspended in (mL): | B7: 10
A8: Time at initial count: | B8: 0.62083333
A9: End thaw | B9: 0.62135417
A10: Volume resuspended in after spin down (mL): | B10: 10 | C10: Time: | D10: 0.62552083
A11: Divided to 6 tubes | B11: 0.62716435 | C11: Volume each tube: | D11: =1650000*B10/C18 -> 1.673428 | E11: Actual volume: | F11: 1.67
A13: Cell counts after thaw
B14: Tot | C14: Live | D14: Viable
A15: Count 1 | B15: 840000 | C15: 840000 | D15: 1
A16: Count 2 | B16: 1040000 | C16: 1040000 | D16: 1
A17: Count 3 | B17: 1100000 | C17: =D17*B17 -> 1078000 | D17: 0.98
B18: Tot viabal: | C18: =AVERAGE(C15:C17)*B7 -> 9860000
A21: Falcone tube: | B21: 10s | D21: 80s | F21: 140s
B22: 1 | C22: 2 | D22: 3 | E22: 4 | F22: 5 | G22: 6
A23: Start time (Out from centrifuge)
A24: Cells given to injector
A25: Start Time inject
A26: End time injection
A27: Start time flush:
A28: End time flush
A29: Tube handed to Jesper
A30: Volume handed (uL) | B30: 100 | C30: 50 | D30: 50 | E30: 50 | F30: 50 | G30: 50
A31: Cells handed to injector | B31: 1600000 | C31: 1600000 | D31: 1600000 | E31: 1600000 | F31: 1600000 | G31: 1600000
A32: After Syringe (uL) | B32: 40 | C32: 40 | D32: 50 | E32: 55 | F32: 50 | G32: 50
A33: Cells injected | B33: =B31*B32/B30 -> 640000 | C33: =C31*C32/C30 -> 1280000 | D33: =D31*D32/D30 -> 1600000 | E33: =E31*E32/E30 -> 1760000 | F33: =F31*F32/F30 -> 1600000 | G33: =G31*G32/G30 -> 1600000
A35: Volume flushed (uL) | B35: 100 | C35: 100 | D35: 100 | E35: 100 | F35: 100 | G35: 100
A36: Volume before (ml) | B36: 1.1 | C36: 1.1 | D36: 1.1 | E36: 1.1 | F36: 1.1 | G36: 1.1
A37: Volume after | B37: =B36+B32/1000+B35/1000 -> 1.24 | C37: =C36+C32/1000+C35/1000 -> 1.24 | D37: =D36+D32/1000+D35/1000 -> 1.25 | E37: =E36+E32/1000+E35/1000 -> 1.255 | F37: =F36+F32/1000+F35/1000 -> 1.25 | G37: =G36+G32/1000+G35/1000 -> 1.25
A38: JESPER COUNTS | B38: 0.65190972 | C38: 0.65763889 | D38: 0.66255787 | E38: 0.66969907 | F38: 0.67530093 | G38: 0.68206019
A39: Comments: | B39: White material end of cath
A40: Count 1 cells/ml | B40: 920000 | C40: 980000 | D40: 800000 | E40: 1000000 | F40: 660000 | G40: 900000
A41: Count 1 viability | B41: 0.87 | C41: 0.9 | D41: 0.9 | E41: 0.98 | F41: 0.91 | G41: 0.95
A42: Count 2 cells/ml | B42: 910000 | C42: 940000 | D42: 680000 | E42: 920000 | F42: 760000 | G42: 620000
A43: Count 2 viability | B43: 0.89 | C43: 0.9 | D43: 0.9 | E43: 0.92 | F43: 1 | G43: 0.98
A44: Count 3 cells/ml | B44: 860000 | C44: 780000 | D44: 640000 | E44: 860000 | F44: 560000 | G44: 700000
...

Sheet 30000 cells ul small
A1: Thawing
A2: Media prepared: | B2: 0.43888889
A3: Tube Nr: | B3: 10M 22
A4: Taken from freezer: | B4: 0.43194444
A5: Arrival at water bath | B5: 0.44097222
A6: Taken out from the water bath
A7: Volume resuspended in (mL): | B7: 10
A8: Time at initial count:
A9: End thaw
A10: Volume resuspended in after spin down (mL): | B10: 10 | C10: Time:
A11: Divided to 6 tubes | C11: Volume each tube: | D11: =1650000*B10/C19 -> 1.8539326 | E11: Actual volume: | F11: 1.67
A13: Cell counts after thaw
B14: Tot | C14: Live | D14: Dead | E14: Hemo
A15: Count 1 | B15: =E15*2*10000 -> 840000 | C15: =(E15-D15)*10000*2 -> 840000 | D15: 0 | E15: 42
A16: Count 2 | B16: =E16*2*10000 -> 1000000 | C16: =(E16-D16)*10000*2 -> 960000 | D16: 2 | E16: 50
A17: Count 3 | B17: =E17*2*10000 -> 860000 | C17: =(E17-D17)*10000*2 -> 860000 | D17: 0 | E17: 43
A18: Count 4 | B18: =E18*2*10000 -> 940000 | C18: =(E18-D18)*10000*2 -> 900000 | D18: 2 | E18: 47
B19: Tot viabal: | C19: =AVERAGE(C15:C18)*B7 -> 8900000
A22: Falcone tube: | B22: 10s | D22: 80s | F22: 140s
B23: 1 | C23: 2 | D23: 3 | E23: 4 | F23: 5 | G23: 6
A24: Start time (Out from centrifuge)
A25: Cells given to injector | B25: 0.48333333 | C25: 0.4875 | D25: 0.49097222
A26: Start Time inject | B26: 0.48472222 | C26: 0.4875 | D26: 11.49
A27: End time injection | B27: 8s | C27: 5s | D27: 75 s | E27: 75 se | F27: 126s | G27: 110s
A28: Start time flush: | C28: 0.48819444 | D28: 0.49305556 | E28: 0.49652778 | F28: 0.50069444 | G28: 0.50486111
A29: End time flush | B29: 0.48680556 | C29: 0.48888889 | D29: 0.49375 | E29: 0.49722222 | F29: 0.50138889 | G29: 0.50555556
A30: Tube handed to Jesper
A31: Volume handed (uL) | B31: 100 | C31: 100 | D31: 100 | E31: 100 | F31: 100 | G31: 100
A32: Cells handed to injector | B32: 1600000 | C32: 1600000 | D32: 1600000 | E32: 1600000 | F32: 1600000 | G32: 1600000
A33: After Syringe (uL) | B33: 100 | C33: 100 | D33: 70 | E33: 100 | F33: 100 | G33: 100
A34: Cells injected | B34: =B32*B33/B31 -> 1600000 | C34: =C32*C33/C31 -> 1600000 | D34: =D32*D33/D31 -> 1120000 | E34: =E32*E33/E31 -> 1600000 | F34: =F32*F33/F31 -> 1600000 | G34: =G32*G33/G31 -> 1600000
A36: Volume flushed (uL) | B36: 100 | C36: 100 | D36: 100 | E36: 100 | F36: 100 | G36: 100
A37: Volume before (ml) | B37: 1.1 | C37: 1.1 | D37: 1.1 | E37: 1.1 | F37: 1.1 | G37: 1.1
A38: Volume after | B38: =B37+B33/1000+B36/1000 -> 1.3 | C38: =C37+C33/1000+C36/1000 -> 1.3 | D38: =D37+D33/1000+D36/1000 -> 1.27 | E38: =E37+E33/1000+E36/1000 -> 1.3 | F38: =F37+F33/1000+F36/1000 -> 1.3 | G38: =G37+G33/1000+G36/1000 -> 1.3
A39: JESPER COUNTS
A40: Comments:
A41: Count 1 alive | B41: 55 | C41: 52 | D41: 34 | E41: 32 | F41: 27 | G41: 21
A42: Count 1 Dead | B42: 2 | C42: 6 | D42: 1 | E42: 3 | F42: 0 | G42: 1
A43: Count 2 alive | B43: 55 | C43: 51 | D43: 32 | E43: 38 | F43: 26 | G43: 23
A44: Count 2 Dead | B44: 2 | C44: 7 | D44: 2 | E44: 3 | F44: 1 | G44: 4
...

Sheet 30000 cells ul Large
A1: Thawing
A2: Media prepared:
A3: Tube Nr: | B3: 10M 22
A4: Taken from freezer:
A5: Arrival at water bath
A6: Taken out from the water bath
A7: Volume resuspended in (mL): | B7: 10
A8: Time at initial count:
A9: End thaw
A10: Volume resuspended in after spin down (mL): | B10: 10 | C10: Time:
A11: Divided to 6 tubes | C11: Volume each tube: | D11: =1650000*B10/C19 -> 1.6751269 | E11: Actual volume: | F11: 1.67
A13: Cell counts after thaw
B14: Tot | C14: Live | D14: Dead | E14: Hemo
A15: Count 1 | B15: =E15*2*10000 -> 1060000 | C15: =(E15-D15)*10000*2 -> 1040000 | D15: 1 | E15: 53
A16: Count 2 | B16: =E16*2*10000 -> 920000 | C16: =(E16-D16)*10000*2 -> 900000 | D16: 1 | E16: 46
A17: Count 3 | B17: =E17*2*10000 -> 1020000 | C17: =(E17-D17)*10000*2 -> 1000000 | D17: 1 | E17: 51
A18: Count 4 | B18: =E18*2*10000 -> 1020000 | C18: =(E18-D18)*10000*2 -> 1000000 | D18: 1 | E18: 51
B19: Tot viabal: | C19: =AVERAGE(C15:C18)*B7 -> 9850000
A22: Falcone tube: | B22: 10s | D22: 80s | F22: 140s
B23: 1 | C23: 2 | D23: 3 | E23: 4 | F23: 5 | G23: 6
A24: Start time (Out from centrifuge)
A25: Cells given to injector
A26: Start Time inject
A27: End time injection | B27: 8s | C27: 5s | D27: 65s | E27: 77s | F27: 143s | G27: 141s
A28: Start time flush:
A29: End time flush
A30: Tube handed to Jesper
A31: Volume handed (uL) | B31: 100 | C31: 100 | D31: 100 | E31: 100 | F31: 100 | G31: 100
A32: Cells handed to injector | B32: 1600000 | C32: 1600000 | D32: 1600000 | E32: 1600000 | F32: 1600000 | G32: 1600000
A33: After Syringe (uL) | B33: 100 | C33: 100 | D33: 100 | E33: 100 | F33: 100 | G33: 100
A34: Cells injected | B34: =B32*B33/B31 -> 1600000 | C34: =C32*C33/C31 -> 1600000 | D34: =D32*D33/D31 -> 1600000 | E34: =E32*E33/E31 -> 1600000 | F34: =F32*F33/F31 -> 1600000 | G34: =G32*G33/G31 -> 1600000
A36: Volume flushed (uL) | B36: 200 | C36: 200 | D36: 200 | E36: 200 | F36: 200 | G36: 200
A37: Volume before (ml) | B37: 1 | C37: 1 | D37: 1 | E37: 1 | F37: 1 | G37: 1
A38: Volume after | B38: =B37+B33/1000+B36/1000 -> 1.3 | C38: =C37+C33/1000+C36/1000 -> 1.3 | D38: =D37+D33/1000+D36/1000 -> 1.3 | E38: =E37+E33/1000+E36/1000 -> 1.3 | F38: =F37+F33/1000+F36/1000 -> 1.3 | G38: =G37+G33/1000+G36/1000 -> 1.3
A39: Counts
A40: Comments:
A41: Count 1 alive | B41: 32 | C41: 34 | D41: 36 | E41: 30 | F41: 27 | G41: 42
A42: Count 1 Dead | B42: 13 | C42: 15 | D42: 9 | E42: 5 | F42: 3 | G42: 7
A43: Count 2 alive | B43: 20 | C43: 24 | D43: 40 | E43: 40 | F43: 34 | G43: 50
A44: Count 2 Dead | B44: 15 | C44: 13 | D44: 6 | E44: 4 | F44: 4 | G44: 5
...

Sheet small_30000
A1: Time | B1: Viability | C1: SD_v | D1: Retention | E1: SD_r
A2: 30 | B2: 0.90688331 | C2: 0.017511901 | D2: 0.869375 | E2: 0.067197238
A3: 120 | B3: 0.93998939 | C3: 0.048579831 | D3: 0.71369048 | E3: 0.16432463
A4: 240 | B4: 0.94277884 | C4: 0.032659863 | D4: 0.39541667 | E4: 0.049997917

Sheet Large_30000
A1: Time | B1: Viability | C1: SD_v | D1: Retention | E1: SD_r
A2: 30 | B2: 0.47681781 | C2: 0.017511901 | D2: 0.446875 | E2: 0.087055119
A3: 120 | B3: 0.83615628 | C3: 0.048579831 | D3: 0.60395833 | E3: 0.066934747
A4: 240 | B4: 0.86708906 | C4: 0.032659863 | D4: 0.62833333 | E4: 0.15910623

Sheet Pancreatic islets
A1: Info | C1: Ulrik.birgersson@smartcella.com
A2: Media prepared:
A3: Cell age
A4: Amount at harvest | B4: 10000
A5: Arrival at cell lab | B5: 0.54791667
A6: Taken out from the water bath
A7: Volume resuspended in (mL): | B7: 10
A8: Time at initial count:
A9: End thaw
A10: Volume resuspended in after spin down (mL): | B10: 10 | C10: Time:
A11: Amount in each
A12: Divided to 6 tubes | C12: Volume each tube: | D12: =B11*B10/C20 -> #DIV/0! | E12: Actual volume:
A14: Cell counts after thaw
B15: Tot | C15: Live | D15: Dead | E15: Hemo
A16: Count 1 | B16: =E16*2*10000 -> 0 | C16: =(E16-D16)*10000*2 -> 0
A17: Count 2 | B17: =E17*2*10000 -> 0 | C17: =(E17-D17)*10000*2 -> 0
A18: Count 3 | B18: =E18*2*10000 -> 0 | C18: =(E18-D18)*10000*2 -> 0
A19: Count 4 | B19: =E19*2*10000 -> 0 | C19: =(E19-D19)*10000*2 -> 0
B20: Tot viabal: | C20: =AVERAGE(C16:C19)*B7 -> 0
A23: Falcone tube: | B23: 10s | D23: 80s | F23: 140s
B24: 1 | C24: 2 | D24: 3 | E24: 4 | F24: 5 | G24: 6
A25: Start time pipett | B25: 0.56458333
A26: End time pipett | B26: 0.56527778
A27: Move to new plate | B27: 0.56666667
A28: Start time count | B28: 0.56701389
A29: End time count | B29: 0.57199074
A30: Wash start | B30: 0.57291667
A31: Settle start | B31: 0.61582176
A32: Count rest | B32: 0.57548611
A33: Aspirate | B33: 0.57824074
A34: push to well | B34: 0.58113426
A35: Needle | B35: 21G (0.8 x 40mm)
A36: Wash start
A37: End time injection
A38: Start time flush: | D38: Pyronics 0.1 +BSA 0.1
A39: cells per agg | B39: 400
A40: size um | B40: 115 | C40: 110 | D40: 115
A41: Volume handed (uL) | B41: 100 | C41: 300 | D41: 300 | E41: 100 | F41: 100 | G41: 100
A42: cells left | B42: 46
A43: Cells at start | B43: 532 | C43: 1200 | D43: 1200
...

Sheet Islets summery
A1: Run | B1: 1 | C1: 2 | D1: 3
A2: Cells injected | B2: 432 | D2: 1200
A3: Injection volume | B3: 100 | C3: 300 | D3: 300
A4: Wash volume | B4: 100 | C4: 300 | D4: 300
A5: Count 1 alive | B5: 94 | C5: 586 | D5: =241+57+87 -> 385
A6: Count 1 dead | B6: 3 | C6: 10 | D6: 1
A7: Count 2 alive | B7: 34 | C7: 54 | D7: 92
A8: Count 2 dead | B8: 0 | C8: 25 | D8: 3
A9: Count 3 alive | B9: 93 | C9: 11 | D9: 26
A10: Count 3 dead | B10: 2 | C10: 11 | D10: 2
A11: Count 4 alive | C11: 15 | D11: 12
A12: Count 4 dead | C12: 15 | D12: 12
A13: Parameters | B13: PBS | C13: PBS | D13: PBS+Pyronics+BSA
A14: Time from incubator | B14: =33*60+22 -> 2002 | C14: =6*60+4 -> 364 | D14: =5*60+40 -> 340

Sheet Plan
B1: Step | C1: Approx time | D1: Comment
A2: 1 | B2: 500 cell aggregates
A3: 2
A4: 3
A5: 4
A6: 5
A7: 6
A9: Stem cell aggregates | B9: 10000
A10: Fused islets | B10: 35000 | C10: 200 um
A11: islts fuse

Sheet Sheet3
A1: well 1
A2: 500 cells
